---
title: Обработка ошибок в асинхронных функциях
description: В ES2017 появились асинхронные функции, которые позволяют сделать асинхронные вызовы более плоскими и похожими на синхронные. На первый взгляд в них есть проблемы с обработкой ошибок, но их можно обойти.
datetime: 2018-05-17T21:00
slug: /blog/error-handling-async-await
tags:
  - dev
  - favorite
  - fp
---

# Обработка ошибок в асинхронных функциях

В ES2017 появились [асинхронные функции](https://developer.mozilla.org/ru/docs/Web/JavaScript/Reference/Statements/async_function), которые позволяют сделать асинхронные вызовы более плоскими и похожими на синхронные.

Асинхронные функции работают на [промисах](https://learn.javascript.ru/promise). Очень грубо говоря _await_ внутри асинхронной функции как бы приостанавливает её выполнение, ждёт, когда зарезолвится промис, указанный после него, и возвращает результат.

И на первый взгляд в асинхронных функциях есть проблемы с обработкой ошибок.

## Промисы

Допустим, у нас есть функция _loadPost_, которая получает с сервера статью и работает на промисах. Метод _fetch_ отправляет запрос на указанный адрес, и возвращает промис, который мы в дальнейшем можем обработать.

Если всё хорошо, получаем данные с помощью _.json_, который тоже возвращает промис. Если что-то пошло не так, отловим ошибку в _.catch_.

```
const loadPost = (postId) =>
  fetch(`https://jsonplaceholder.typicode.com/posts/${postId}`)
    .then(response => response.json())
    .then(data => console.log(data.title))
    .catch(e => console.log(`Error! ${e}`))

loadPost(1)
```

## Асинхронные функции

Попробуем переписать эту функцию, используя _async/await_. Делаем её асинхронной с помощью ключевого слова _async_, без этого бы не сможем использовать _await_ внутри.

Вторая строка совершает запрос, _await_ «разворачивает» промис и возвращает значение, которое записывается в переменную _response_. Третья строка получает джейсон и записывает значение в переменную _data_.

```
const loadPost = async (postId) => {
  const response = await fetch(`https://jsonplaceholder.typicode.com/posts/${postId}`)
  const data = await response.json()
  console.log(data.title)
}

loadPost(1)
```

Пока запрос проходит без ошибок у нас всё хорошо. Но если что-то пойдёт не так, выскочит исключение:

```
Uncaught (in promise) TypeError: Failed to fetch
```

## Обработка ошибок

Окей, используем _try-catch_, чтобы отловить ошибку:

```
const loadPost = async (postId) => {
  try {
    const response = await fetch(`https://jsonplaceholder.typicode.com/posts/${postId}`)
    const data = await response.json()
    console.log(data.title)
  }
  catch(e) {
    console.log(`Error! ${e}`)
  }
}

loadPost(1)
```

Вроде нормально, но функция стала больше, да и запросы могут быть разными, а каждый раз писать _try-catch_ запарно.

Вспоминаем, что асинхронная функция возвращает промис, поэтому можно использовать _.catch_, чтобы отловить ошибку:

```
const loadPost = async (postId) => {
  const response = await fetch(`https://jsonplaceholder.typicode.com/posts/${postId}`)
  const data = await response.json()
  console.log(data.title)
}

loadPost(1)
  .catch(e => console.log(`Error! ${e}`))
```

Это решает проблему с повторами _try-catch_, но не решает проблему с дублированием кода. Здесь может помочь [функция высшего порядка](https://ru.wikipedia.org/wiki/Функция_высшего_порядка).

```
const loadPost = async (postId) => {
  const response = await fetch(`https://jsonplaceholder.typicode.com/posts/${postId}`)
  const data = await response.json()
  console.log(data.title)
}

// функция высшего порядка по очереди «запоминает»
// обработчик ошибок, сам запрос, аргументы для запроса
const tryCatchWrapper = (handleError) => (reqFn) => (...args) =>
  reqFn(...args).catch(handleError)

// обработчик ошибок
const handleError = e =>
  console.log(`Error! ${e}`)

// запомнили функцию для обработки ошибок
const errorHandlerWrapper = tryCatchWrapper(handleError)

// запомнили, какой запрос хотим выполнить
const safelyLoadPost = errorHandlerWrapper(loadPost)

// выполняем этот запрос
safelyLoadPost(1)
```

Запрос остался без изменений, но добавилась функция _tryCatchWrapper_. Она принимает как аргумент функцию _handleError_, которая будет обрабатывать исключения, и возвращает новую функцию.

Эта новая функция принимает функцию запроса, который мы собираемся отправлять, и возвращает ещё одну функцию. Эта конечная функция принимает параметры, которые будет передавать в функцию запроса, когда мы вызовем её.

По-умному это ещё называю [каррированием](https://ru.wikipedia.org/wiki/Каррирование): когда мы из одной функции с несколькими аргументами делаем несколько функций, которые принимают по одному аргументу. Так мы можем «запоминать» аргументы, не вызывая функцию сразу, а вызывать её потом.

Всё это вместе позволяет написать несколько обработчиков ошибок, которые будут применять разные функции в зависимости от наших целей. Например, если мы захотим использовать другой обработчик для какого-то запроса, мы можем передать как аргумент другую функцию:

```
// первый обработчик
const handleError = e =>  console.log(`Error! ${e}`)
const errorHandlerWrapper = tryCatchWrapper(handleError)

// другой
const handleErrorDifferently = e => console.log(`Wow! It is all different now`)
const otherErrorHandlerWrapper = tryCatchWrapper(handleErrorDifferently)
```

И при этом не будет дублирования кода, потому что вся обработка находится внутри _tryCatchWrapper_.

## Ссылки по теме

- [Метод _fetch_](https://learn.javascript.ru/fetch)
- [Промис](https://learn.javascript.ru/promise)
- [Асинхронные функции](https://developer.mozilla.org/ru/docs/Web/JavaScript/Reference/Statements/async_function)
- [Функции высшего порядка](https://ru.wikipedia.org/wiki/Функция_высшего_порядка)
- [Каррирование](https://ru.wikipedia.org/wiki/Каррирование)
- [Видос об асинхронных функциях](https://www.youtube.com/watch?v=568g8hxJJp4)
